<?xml version="1.0"?>
<robot xmlns:xacro="http://www.ros.org/wiki/xacro" >

    <xacro:include filename="inertial_macros.xacro"/>
    <xacro:include filename="robot_params.xacro"/>

    <!-- BASE LINK -->
    <link name="base_link"/>

    <!-- CHASSIS -->
    <joint name="chassis_joint" type="fixed">
        <parent link="base_link"/>
        <child link="chassis"/>
        <origin xyz="0 0 0"/>
    </joint>

    <link name="chassis">
        <visual>
            <origin xyz="${chassis_origin_x} ${chassis_origin_y} ${chassis_origin_z}"/>
            <geometry>
                <box size="${chassis_length} ${chassis_width} ${chassis_height}"/>
            </geometry>
            <material name="white"/>
        </visual>
        <collision>
            <origin xyz="${chassis_origin_x} ${chassis_origin_y} ${chassis_origin_z}"/>
            <geometry>
                <box size="${chassis_length} ${chassis_width} ${chassis_height}"/>
            </geometry>
        </collision>
        <xacro:inertial_box mass="${chassis_mass}" x="${chassis_length}" y="${chassis_width}" z="${chassis_height}">
            <origin xyz="0 0 0.0455" rpy="0 0 0"/>
        </xacro:inertial_box>
    </link>

    <!-- LEFT FRONT WHEEL -->
    <joint name="left_front_wheel_joint" type="continuous">
        <parent link="base_link"/>
        <child link="left_front_wheel"/>
        <origin xyz="${wheel_x_offset} ${wheel_y_offset} ${wheel_z_offset}" rpy="-${pi/2} 0 0"/>
        <axis xyz="0 0 1"/>

        <limit effort="${wheel_effort}" velocity="${wheel_velocity}"/>
        <dynamics damping="${wheel_damping}" friction="${wheel_friction}"/>
    </joint>

    <link name="left_front_wheel">
        <visual>
            <geometry>
                <cylinder radius="${wheel_radius}" length="${wheel_length}"/>
            </geometry>
            <material name="blue"/>
        </visual>
        <collision>
            <geometry>
                <cylinder radius="${wheel_radius}" length="${wheel_length}"/>
            </geometry>
        </collision>
        <xacro:inertial_cylinder mass="${wheel_mass}" length="${wheel_length}" radius="${wheel_radius}">
            <origin xyz="0 0 0" rpy="0 0 0"/>
        </xacro:inertial_cylinder>
    </link>

    <!-- RIGHT FRONT WHEEL -->
    <joint name="right_front_wheel_joint" type="continuous">
        <parent link="base_link"/>
        <child link="right_front_wheel"/>
        <origin xyz="${wheel_x_offset} -${wheel_y_offset} ${wheel_z_offset}" rpy="-${pi/2} 0 0"/>
        <axis xyz="0 0 1"/>

        <limit effort="${wheel_effort}" velocity="${wheel_velocity}"/>
        <dynamics damping="${wheel_damping}" friction="${wheel_friction}"/>
    </joint>

    <link name="right_front_wheel">
        <visual>
            <geometry>
                <cylinder radius="${wheel_radius}" length="${wheel_length}"/>
            </geometry>
            <material name="blue"/>
        </visual>
        <collision>
            <geometry>
                <cylinder radius="${wheel_radius}" length="${wheel_length}"/>
            </geometry>
        </collision>
        <xacro:inertial_cylinder mass="${wheel_mass}" length="${wheel_length}" radius="${wheel_radius}">
            <origin xyz="0 0 0" rpy="0 0 0"/>
        </xacro:inertial_cylinder>
    </link>

    <!-- LEFT REAR WHEEL -->
    <joint name="left_rear_wheel_joint" type="continuous">
        <parent link="base_link"/>
        <child link="left_rear_wheel"/>
        <origin xyz="-${wheel_x_offset} ${wheel_y_offset} ${wheel_z_offset}" rpy="-${pi/2} 0 0"/>
        <axis xyz="0 0 1"/>

        <limit effort="${wheel_effort}" velocity="${wheel_velocity}"/>
        <dynamics damping="${wheel_damping}" friction="${wheel_friction}"/>
    </joint>

    <link name="left_rear_wheel">
        <visual>
            <geometry>
                <cylinder radius="${wheel_radius}" length="${wheel_length}"/>
            </geometry>
            <material name="black"/>
        </visual>
        <collision>
            <geometry>
                <cylinder radius="${wheel_radius}" length="${wheel_length}"/>
            </geometry>
        </collision>
        <xacro:inertial_cylinder mass="${wheel_mass}" length="${wheel_length}" radius="${wheel_radius}">
            <origin xyz="0 0 0" rpy="0 0 0"/>
        </xacro:inertial_cylinder>
    </link>

    <!-- RIGHT REAR WHEEL -->
    <joint name="right_rear_wheel_joint" type="continuous">
        <parent link="base_link"/>
        <child link="right_rear_wheel"/>
        <origin xyz="-${wheel_x_offset} -${wheel_y_offset} ${wheel_z_offset}" rpy="-${pi/2} 0 0"/>
        <axis xyz="0 0 1"/>

        <limit effort="${wheel_effort}" velocity="${wheel_velocity}"/>
        <dynamics damping="${wheel_damping}" friction="${wheel_friction}"/>
    </joint>

    <link name="right_rear_wheel">
        <visual>
            <geometry>
                <cylinder radius="${wheel_radius}" length="${wheel_length}"/>
            </geometry>
            <material name="black"/>
        </visual>
        <collision>
            <geometry>
                <cylinder radius="${wheel_radius}" length="${wheel_length}"/>
            </geometry>
        </collision>
        <xacro:inertial_cylinder mass="${wheel_mass}" length="${wheel_length}" radius="${wheel_radius}">
            <origin xyz="0 0 0" rpy="0 0 0"/>
        </xacro:inertial_cylinder>
    </link>

    <!-- GAZEBO MATERIALS -->
    <gazebo reference="chassis">
        <material>Gazebo/White</material>
        <mu1>1.0</mu1>
        <mu2>1.0</mu2>
    </gazebo>

    <gazebo reference="left_front_wheel">
        <material>Gazebo/Blue</material>
        <mu1>1.0</mu1>
        <mu2>1.0</mu2>
    </gazebo>

    <gazebo reference="right_front_wheel">
        <material>Gazebo/Blue</material>
        <mu1>1.0</mu1>
        <mu2>1.0</mu2>
    </gazebo>

    <gazebo reference="left_rear_wheel">
        <material>Gazebo/Black</material>
        <mu1>1.0</mu1>
        <mu2>1.0</mu2>
    </gazebo>

    <gazebo reference="right_rear_wheel">
        <material>Gazebo/Black</material>
        <mu1>1.0</mu1>
        <mu2>1.0</mu2>
    </gazebo>


</robot>