<?xml version="1.0"?>
<robot xmlns:xacro="http://www.ros.org/wiki/xacro" >

    <xacro:include filename="inertial_macros.xacro"/>

    <!-- COLORS -->
    <material name="white">
        <color rgba="1 1 1 1"/>
    </material>

    <material name="orange">
        <color rgba="1 0.3 0.1 1"/>
    </material>

    <material name="blue">
        <color rgba="0.2 0.2 1 1"/>
    </material>

    <material name="black">
        <color rgba="0 0 0 1"/>
    </material>

    <!-- BASE LINK -->
    <link name="base_link">
    </link>

    <!-- CHASSIS -->
    <joint name="chassis_joint" type="fixed">
        <parent link="base_link"/>
        <child link="chassis"/>
        <origin xyz="0 0 0"/>
    </joint>

    <link name="chassis">
        <visual>
            <origin xyz="0 0 0.0455"/>
            <geometry>
                <box size="0.186 0.093 0.091"/>
            </geometry>
            <material name="white"/>
        </visual>
        <collision>
            <origin xyz="0 0 0.0455"/>
            <geometry>
                <box size="0.186 0.093 0.091"/>
            </geometry>
        </collision>
        <xacro:inertial_box mass="0.55" x="0.186" y="0.093" z="0.091">
            <origin xyz="0 0 0.0455" rpy="0 0 0"/>
        </xacro:inertial_box>
    </link>

    <!-- LEFT FRONT WHEEL -->
    <joint name="left_front_wheel_joint" type="continuous">
        <parent link="base_link"/>
        <child link="left_front_wheel"/>
        <origin xyz="0.0676 0.0566 0" rpy="-${pi/2} 0 0"/>
        <axis xyz="0 0 1"/>
    </joint>

    <link name="left_front_wheel">
        <visual>
            <geometry>
                <cylinder radius="0.0325" length="0.02"/>
            </geometry>
            <material name="blue"/>
        </visual>
        <collision>
            <geometry>
                <cylinder radius="0.0325" length="0.02"/>
            </geometry>
        </collision>
        <xacro:inertial_cylinder mass="0.0375" length="0.02" radius="0.0325">
            <origin xyz="0 0 0" rpy="0 0 0"/>
        </xacro:inertial_cylinder>
    </link>

    <!-- RIGHT FRONT WHEEL -->
    <joint name="right_front_wheel_joint" type="continuous">
        <parent link="base_link"/>
        <child link="right_front_wheel"/>
        <origin xyz="0.0676 -0.0566 0" rpy="${pi/2} 0 0"/>
        <axis xyz="0 0 -1"/>
    </joint>

    <link name="right_front_wheel">
        <visual>
            <geometry>
                <cylinder radius="0.0325" length="0.02"/>
            </geometry>
            <material name="blue"/>
        </visual>
        <collision>
            <geometry>
                <cylinder radius="0.0325" length="0.02"/>
            </geometry>
        </collision>
        <xacro:inertial_cylinder mass="0.0375" length="0.02" radius="0.0325">
            <origin xyz="0 0 0" rpy="0 0 0"/>
        </xacro:inertial_cylinder>
    </link>

    <!-- LEFT REAR WHEEL -->
    <joint name="left_rear_wheel_joint" type="continuous">
        <parent link="base_link"/>
        <child link="left_rear_wheel"/>
        <origin xyz="-0.0676 0.0566 0" rpy="-${pi/2} 0 0"/>
        <axis xyz="0 0 1"/>
    </joint>

    <link name="left_rear_wheel">
        <visual>
            <geometry>
                <cylinder radius="0.0325" length="0.02"/>
            </geometry>
            <material name="black"/>
        </visual>
        <collision>
            <geometry>
                <cylinder radius="0.0325" length="0.02"/>
            </geometry>
        </collision>
        <xacro:inertial_cylinder mass="0.0375" length="0.02" radius="0.0325">
            <origin xyz="0 0 0" rpy="0 0 0"/>
        </xacro:inertial_cylinder>
    </link>

    <!-- RIGHT REAR WHEEL -->
    <joint name="right_rear_wheel_joint" type="continuous">
        <parent link="base_link"/>
        <child link="right_rear_wheel"/>
        <origin xyz="-0.0676 -0.0566 0" rpy="${pi/2} 0 0"/>
        <axis xyz="0 0 -1"/>
    </joint>

    <link name="right_rear_wheel">
        <visual>
            <geometry>
                <cylinder radius="0.0325" length="0.02"/>
            </geometry>
            <material name="black"/>
        </visual>
        <collision>
            <geometry>
                <cylinder radius="0.0325" length="0.02"/>
            </geometry>
        </collision>
        <xacro:inertial_cylinder mass="0.0375" length="0.02" radius="0.0325">
            <origin xyz="0 0 0" rpy="0 0 0"/>
        </xacro:inertial_cylinder>
    </link>

    <!-- GAZEBO MATERIALS -->
    <gazebo reference="left_front_wheel">
        <material>Gazebo/Blue</material>
    </gazebo>

    <gazebo reference="right_front_wheel">
        <material>Gazebo/Blue</material>
    </gazebo>

    <gazebo reference="left_rear_wheel">
        <material>Gazebo/Black</material>
    </gazebo>

    <gazebo reference="right_rear_wheel">
        <material>Gazebo/Black</material>
    </gazebo>


</robot>